Workbook

Sheet New Mortgage look
B1: 45760
C2: Value | D2: Current Loan | E2: Current Revolving | F2: 20%Deposit | G2: New Loan | H2: NewRevolving/Cash | I2: Rent | K2: Mortgage Repayment | M2: Net Income after (Mortgate before Tax) | O2: Tax Repayment | Q2: Net Income after (Tax & Mortgate) | S2: Council Rate Repayment | U2: Net Income after (Tax & Mortgate & Rate) | W2: House Insurance Repayment | Y2: Net Income after (Tax & Mortgate & Rate & Insurance) | AA2: Increase Rent to cover all Costs
I4: Weekly | J4: Forthnight | K4: Weekly | L4: Forthnight | M4: Weekly | N4: Forthnight | O4: Weekly | P4: Forthnight | Q4: Weekly | R4: Forthnight | S4: Weekly | T4: Forthnight | U4: Weekly | V4: Forthnight | W4: Weekly | X4: Forthnight | Y4: Weekly | Z4: Forthnight | AA4: Weekly | AB4: Forthnight
B5: Property1 | C5: 100000 | D5: =D56+D57 -> 60000 | E5: 0 | F5: 0 | G5: =D56+D57 -> 60000 | H5: =(C5*0.7)-D5 -> 10000 | I5: 100 | J5: =I5*2 -> 200 | K5: =F56+F57 -> 100 | L5: =G56+G57 -> 200 | M5: =I5-K5 -> 0 | N5: =J5-L5 -> 0 | O5: =E85/52 -> 0 | P5: =E85/26 -> 0 | Q5: =I5-K5-O5 -> 0 | R5: =J5-L5-P5 -> 0 | S5: =E76/52 -> 38.461538 | T5: =E76/26 -> 76.923077 | U5: =I5-K5-O5-S5 -> -38.461538 | V5: =J5-L5-P5-T5 -> -76.923077 | W5: =E67/52 -> 13.846154 | X5: =E67/26 -> 27.692308 | Y5: =I5-K5-O5-S5-W5 -> -52.307692 | Z5: =J5-L5-P5-T5-X5 -> -104.61538 | AA5: =W5+S5+O5+K5-I5 -> 52.307692 | AB5: =X5+T5+P5+L5-J5 -> 104.61538
B6: Propert2 | C6: 150000 | D6: =D52 -> 90000 | E6: 0 | F6: 0 | G6: =D52 -> 90000 | H6: =(C6*0.7)-D6 -> 15000 | I6: 500 | J6: =I6*2 -> 1000 | K6: =F52 -> 40 | L6: =G52 -> 80 | M6: =I6-K6 -> 460 | N6: =J6-L6 -> 920 | O6: =E87/52 -> 31.191154 | P6: =E87/26 -> 62.382308 | Q6: =I6-K6-O6 -> 428.80885 | R6: =J6-L6-P6 -> 857.61769 | S6: =E75/52 -> 38.461538 | T6: =E75/26 -> 76.923077 | U6: =I6-K6-O6-S6 -> 390.34731 | V6: =J6-L6-P6-T6 -> 780.69462 | W6: =E66/52 -> 11.538462 | X6: =E66/26 -> 23.076923 | Y6: =I6-K6-O6-S6-W6 -> 378.80885 | Z6: =J6-L6-P6-T6-X6 -> 757.61769 | AA6: =W6+S6+O6+K6-I6 -> -378.80885 | AB6: =X6+T6+P6+L6-J6 -> -757.61769
B7: Property3 | C7: 170000 | D7: =D49+D50+D51 -> 200000 | E7: 0 | F7: 0 | G7: =D49+D50+D51 -> 200000 | H7: =(C7*0.7)-D7 -> -81000 | I7: 600 | J7: =I7*2 -> 1200 | K7: =F49+F50+F51 -> 60 | L7: =G49+G50+G51 -> 120 | M7: =I7-K7 -> 540 | N7: =J7-L7 -> 1080 | O7: =E86/52 -> 26.022923 | P7: =E86/26 -> 52.045846 | Q7: =I7-K7-O7 -> 513.97708 | R7: =J7-L7-P7 -> 1027.9542 | S7: =E74/52 -> 67.307692 | T7: =E74/26 -> 134.61538 | U7: =I7-K7-O7-S7 -> 446.66938 | V7: =J7-L7-P7-T7 -> 893.33877 | W7: =E65/52 -> 9.2307692 | X7: =E65/26 -> 18.461538 | Y7: =I7-K7-O7-S7-W7 -> 437.43862 | Z7: =J7-L7-P7-T7-X7 -> 874.87723 | AA7: =W7+S7+O7+K7-I7 -> -437.43862 | AB7: =X7+T7+P7+L7-J7 -> -874.87723
B8: Property4 | C8: 180000 | D8: =D53+D54+D55 -> 200000 | E8: 0 | F8: 0 | G8: =D53+D54+D55 -> 200000 | H8: =(C8*0.8)-D8 -> -56000 | I8: 0 | J8: 0 | K8: =F53+F54+F55 -> 135 | L8: =G53+G54+G55 -> 270 | M8: =I8-K8 -> -135 | N8: =J8-L8 -> -270 | O8: 0 | P8: 0 | Q8: =I8-K8-O8 -> -135 | R8: =J8-L8-P8 -> -270 | S8: =E73/52 -> 57.692308 | T8: =E73/26 -> 115.38462 | U8: =I8-K8-O8-S8 -> -192.69231 | V8: =J8-L8-P8-T8 -> -385.38462 | W8: =SUM(E63:E64)/52 -> 11.538462 | X8: =SUM(E63:E64)/26 -> 23.076923 | Y8: =I8-K8-O8-S8-W8 -> -204.23077 | Z8: =J8-L8-P8-T8-X8 -> -408.46154 | AA8: =W8+S8+O8+K8-I8 -> 204.23077 | AB8: =X8+T8+P8+L8-J8 -> 408.46154
B9: Cash/Saving | H9: =D34 -> 26500
B10: Saving for new Investment | C10: =F10/0.3 -> 0 | E10: 0 | F10: =IF(SUM(H5:H9)<=0,0,SUM(H5:H9)) -> 0 | G10: =C10*0.7 -> 0 | H10: 0 | I10: 0 | J10: =I10*2 -> 0 | K10: 0 | L10: 0 | M10: =I10-K10 -> 0 | N10: =J10-L10 -> 0
B11: Total Rents
B12: Total Values / Rents | C12: =SUM(C5:C11) -> 600000 | D12: =SUM(D5:D11) -> 550000 | E12: =SUM(E5:E11) -> 0 | F12: =SUM(F5:F11) -> 0 | G12: =SUM(G5:G11) -> 550000 | H12: =SUM(H5:H9) -> -85500 | I12: =SUM(I5:I10) -> 1200 | J12: =SUM(J5:J10) -> 2400 | K12: =SUM(K5:K10) -> 335 | L12: =SUM(L5:L10) -> 670 | M12: =SUM(M5:M10) -> 865 | N12: =SUM(N5:N10) -> 1730 | O12: =SUM(O5:O10) -> 57.214077 | P12: =SUM(P5:P10) -> 114.42815 | ... AB12: =SUM(AB5:AB10) -> -1119.418
F13: Monthly Costs 13April2025 | H13: Total Monthly Costs | I13: FY2024-2025
B14: Supperanuvation MJ | C14: 50000 | E14: H-Insu 5B Cleary | F14: =F66 -> 50 | H14: Expense (Expenses) | I14: =SUM(F14:F44) -> #REF!
B15: Superanuvation SAM | C15: 30000 | E15: H-Insu 24 Panorama | F15: =F65 -> 40 | H15: =E45&" (Expenses)" -> Properties Tax (Expenses) | I15: =F45 -> 247.92767
C16: =C14+C15 -> 80000 | E16: H-Insu 6/29 Te Koa | F16: =F67 -> 60 | H16: Mortgage (Expenses) | I16: =F58*52/12 -> 1451.6667
E17: H-Insu 8 Denning | F17: =F63 -> 20 | H17: Salary-KiwiSavers (Expenses) | I17: =F46 -> 283.3325
B18: Car | C18: 20000 | E18: C-Insu 8 Denning | F18: =F64 -> 30 | H18: Salary- ACC | I18: =E82 -> 103.605
E19: Car Insu | F19: =F62 -> 4.1666667 | H19: Salary - Tax | I19: =F82 -> 1934.48
B20: Credit Card-KiwiBank-SAM | C20: 500 | D20: 0 | E20: Life | F20: =F68 -> 70 | H20: Salary Income Gross | I20: =H82+F82+E82+D82 -> 7083.3333
B21: Credit Card-KiwiBank-SAM | C21: 1000 | D21: 0 | E21: Health(Sam) | F21: =F69 -> 40 | H21: Rental Income Gross | I21: =SUM(I5:I7)*52/12 -> 5200
B22: Credit Card-ASB-MJ | C22: 2 | D22: 0 | E22: 24 Panorama Rate | F22: =F74 -> 291.66667 | H22: Total Remaining | I22: =SUM(I20:I21)-SUM(I14:I19) -> #REF!
E23: 5B cleary Rate | F23: =F75 -> 166.66667
B24: Deposit | C24: =B1 -> 45760 | E24: 6/29 Te Koa Rate | F24: =F76 -> 166.66667 | I24: Value | J24: Current Loan | K24: Value/Loan ROI
B25: Kiwibank Saving | C25: 38-9016-xxxxx-13 | D25: 15000 | E25: 8 Denning Rate | F25: =F73 -> 250 | H25: =B6 -> Propert2 | I25: =C6 -> 150000 | J25: =D6 -> 90000 | K25: =J25/I25 -> 0.6
B26: KiwiBank | C26: 38-9016-xxxxx-01 | D26: 11500 | E26: Groceries | F26: =GETPIVOTDATA("Amount",Expense!$A$6,"Categories","Groceries")/-12 -> 1035.7667 | H26: =B7 -> Property3 | I26: =C7 -> 170000 | J26: =D7 -> 200000 | K26: =J26/I26 -> 1.1764706
D27: 0 | E27: Medical | F27: =GETPIVOTDATA("Amount",Expense!$A$6,"Categories","Medical")/-12 -> 127.4525 | H27: =B5 -> Property1 | I27: =C5 -> 100000 | J27: =D5 -> 60000 | K27: =J27/I27 -> 0.6
D28: 0 | E28: Personal Care | F28: =GETPIVOTDATA("Amount",Expense!$A$6,"Categories","Personal Care","SubCategories","Personal Care")/-12 -> 59.6925 | H28: =B8 -> Property4 | I28: =C8 -> 180000 | J28: =D8 -> 200000 | K28: =J28/I28 -> 1.1111111
D29: 0 | E29: Gym | F29: =GETPIVOTDATA("Amount",Expense!$A$6,"Categories","Recreational & Entertainment","SubCategories","Gym ")/-12 -> 85.179167 | H29: Total | I29: =SUM(I25:I28) -> 600000 | J29: =SUM(J25:J28) -> 550000 | K29: =J29/I29 -> 0.91666667
D30: 0 | E30: Entertainment | F30: =GETPIVOTDATA("Amount",Expense!$A$6,"Categories","Recreational & Entertainment","SubCategories","Entertainment")/-12 -> 203.25333 | H30: DTI | I30: =((C81+C80)*7)+(((I5+I6+I7)*52*0.7)*7) -> 900760 | J30: =J29 -> 550000 | K30: =I30-J30 -> 350760
D31: 0 | E31: Dinning | F31: =GETPIVOTDATA("Amount",Expense!$A$6,"Categories","Recreational & Entertainment","SubCategories","Dining Out ")/-12 -> 281.7225 | H31: DTI Weekly Rental Income needed | K31: =-((K30/7)/52)/0.7 -> -1376.6091
D32: 0 | E32: Shopping | F32: =GETPIVOTDATA("Amount",Expense!$A$6,"Categories","Personal Care","SubCategories","Clothing & Footwear")/-12 -> 238.94667 | H32: DTI Annual Salary Income needed | K32: =-(K30/7) -> -50108.571
D33: 0 | E33: Travel | F33: =GETPIVOTDATA("Amount",Expense!$A$6,"Categories","Recreational & Entertainment","SubCategories","Travel ")/-12 -> 1448.4483
B34: Total | D34: =SUM(D25:D33) -> 26500 | E34: Home Expense | F34: =GETPIVOTDATA("Amount",Expense!$A$6,"Categories","8 Denning Place ","SubCategories","Home Expense")/-12 -> 183.7525 | H34: 1/4 DTI - increase rent for each property | K34: =(K31/4)/3 -> -114.71743
E35: Transport Cost | F35: =GETPIVOTDATA("Amount",Expense!$A$6,"Categories","Transport")/-12 -> 338.52167 | H35: 3/4 DTI - increase Salary for both | K35: =(K32*3)/4 -> -37581.429
E36: Other Expenses | F36: =GETPIVOTDATA("Amount",Expense!$A$6,"Categories","Other")/-12 -> 789.5325 | H36: DTI - increase salary each | K36: =K35/2 -> -18790.714
E37: Immigration | F37: =GETPIVOTDATA("Amount",Expense!$A$6,"Categories","Immigration")/-12 -> #REF!
E38: Apple storage | F38: =GETPIVOTDATA("Amount",Expense!$A$6,"Categories","Telephone & Internet","SubCategories","AppleStorage")/-12 -> 14.120833
E39: US Mobile | F39: =GETPIVOTDATA("Amount",Expense!$A$6,"Categories","Telephone & Internet","SubCategories","US Mobile ")/-12 -> 12.029167
E40: Water | F40: =GETPIVOTDATA("Amount",Expense!$A$6,"Categories","8 Denning Place ","SubCategories","Water")/-12 -> 49.608333
E41: MyRentCharge | F41: =(GETPIVOTDATA("Amount",Expense!$A$6,"Categories","24 Panorama Road ","SubCategories","MyRentCharge ")+GETPIVOTDATA("Amount",Expense!$A$6,"Categories","5B Cleary Road ","SubCategories","MyRentCharge "))/-12 -> 18.7075
...

Sheet Expense
A1: Years (Date) | B1: (All)
A2: Quarters (Date) | B2: (All)
A3: Months (Date) | B3: (All)
A4: Date | B4: (All)
A6: Row Labels | B6: Sum of Amount
A7: 24 Panorama Road | B7: 23638.87
A8: Council Rates | B8: -1947.02
A9: Council Rates | B9: -1947.02
A10: House Insurance | B10: -896.87
A11: House Insurance | B11: -896.87
A12: Income | B12: 24145.15
A13: Rent | B13: 24145.15
A14: Mortgage | B14: 2446.43
A15: Interest | B15: -38255.6
A16: RePayment | B16: 40702.03
A17: MyRentCharge | B17: -108.82
A18: MyRentCharge | B18: -108.82
... A134: Grand Total | B134: 141066.99

Sheet Assets
B3: Assets
C4: Saving & Cash | H4: Linda Loan Assest
D5: SAM | E5: ='New Mortgage look'!B26 -> KiwiBank | F5: ='New Mortgage look'!C26 -> 38-9016-xxxxx-01 | G5: ='New Mortgage look'!D26 -> 11500 | H5: 0
D6: SAM | E6: ='New Mortgage look'!B25 -> Kiwibank Saving | F6: ='New Mortgage look'!C25 -> 38-9016-xxxxx-13 | G6: ='New Mortgage look'!D25 -> 15000
D7: MJ | E7: ='New Mortgage look'!B28 -> 0 | F7: ='New Mortgage look'!C28 -> 0 | G7: ='New Mortgage look'!D28 -> 0 | H7: 0
D8: MJ | E8: ='New Mortgage look'!B27 -> 0 | F8: ='New Mortgage look'!C27 -> 0 | G8: ='New Mortgage look'!D27 -> 0 | H8: 0
C9: Superannuation
D10: MJ | E10: ='New Mortgage look'!B14 -> Supperanuvation MJ | G10: ='New Mortgage look'!C14 -> 50000
D11: SAM | E11: ='New Mortgage look'!B15 -> Superanuvation SAM | G11: ='New Mortgage look'!C15 -> 30000
C12: Property
D13: MJ | E13: ='New Mortgage look'!B7 -> Property3 | G13: ='New Mortgage look'!C7 -> 170000
D14: SAM | E14: ='New Mortgage look'!B6 -> Propert2 | G14: ='New Mortgage look'!C6 -> 150000
D15: MJ&SAM | E15: ='New Mortgage look'!B8 -> Property4 | G15: ='New Mortgage look'!C8 -> 180000
D16: MJ&SAM | E16: ='New Mortgage look'!B5 -> Property1 | G16: ='New Mortgage look'!C5 -> 100000
C17: Vehicle
D18: SAM | E18: ='New Mortgage look'!B18 -> Car | G18: ='New Mortgage look'!C18 -> 20000
C19: Contents
D20: MJ&SAM | E20: ='New Mortgage look'!C64 -> Property4 | F20: ='New Mortgage look'!D64 -> P0000xxxxx96 | G20: ='New Mortgage look'!H64 -> 20000
B21: Summary
C22: MJ | G22: =G10+G13 -> 220000 | H22: =H7+H10+H13 -> 0
C23: SAM | G23: =G5+G6+G11+G14+G18 -> 226500 | H23: =H5+H6+H11+H14+H18 -> 0
C24: SAM&MJ | G24: =G15+G16+G20 -> 300000 | H24: =H15+H16+H20 -> 0
B26: Category
C27: Saving & Cash | F27: =G27/$G$33 -> 0.035498995 | G27: =SUM(G5:G8) -> 26500 | H27: =SUM(H5:H8) -> 0
C28: Superannuation | F28: =G28/$G$33 -> 0.10716678 | G28: =SUM(G10:G11) -> 80000 | H28: =SUM(H10:H11) -> 0
C29: Property | F29: =G29/$G$33 -> 0.80375084 | G29: =SUM(G13:G16) -> 600000 | H29: =SUM(H13:H16) -> 0
C30: Vehicle | F30: =G30/$G$33 -> 0.026791695 | G30: =SUM(G18) -> 20000 | H30: =SUM(H18) -> 0
C31: Contents | F31: =G31/$G$33 -> 0.026791695 | G31: =SUM(G20) -> 20000 | H31: =SUM(H20) -> 0
B33: Total | G33: =SUM(G22:G24) -> 746500 | H33: =SUM(H22:H24) -> 0

Sheet Liabilities
B3: Liabilities
C4: Credit Cards | I4: Linda Loan Assest
D5: MJ | E5: ='New Mortgage look'!B22 -> Credit Card-ASB-MJ | H5: ='New Mortgage look'!C22 -> 2
D6: SAM | E6: ='New Mortgage look'!B20 -> Credit Card-KiwiBank-SAM | H6: ='New Mortgage look'!C20 -> 500
D7: SAM | E7: ='New Mortgage look'!B21 -> Credit Card-KiwiBank-SAM | H7: ='New Mortgage look'!C21 -> 1000
C8: Mortgage
D9: MJ
E10: ='New Mortgage look'!B7 -> Property3 | J10: Rate
F11: ='New Mortgage look'!B49 -> Home Loan ANZ 1 - 24 Panorama | G11: ='New Mortgage look'!C49 -> xxxxx-1001 | H11: ='New Mortgage look'!D49 -> 50000 | J11: ='New Mortgage look'!E49 -> 0.0499
F12: ='New Mortgage look'!B50 -> Home Loan ANZ 2 - 24 Panorama | G12: ='New Mortgage look'!C50 -> xxxxx-1002 | H12: ='New Mortgage look'!D50 -> 70000 | J12: ='New Mortgage look'!E50 -> 0.0515
F13: ='New Mortgage look'!B51 -> Home Loan ANZ 3 - 24 Panorama | G13: ='New Mortgage look'!C51 -> xxxxx-1003 | H13: ='New Mortgage look'!D51 -> 80000 | J13: ='New Mortgage look'!E51 -> 0.0579
D14: SAM
E15: ='New Mortgage look'!B6 -> Propert2
F17: ='New Mortgage look'!B52 -> KiwiBank 1 - 5B Cleary Road | G17: ='New Mortgage look'!C52 -> 38-9016-xxxxx-10 | H17: ='New Mortgage look'!D52 -> 90000 | J17: ='New Mortgage look'!E52 -> 0.0654
D18: MJ&SAM
E19: ='New Mortgage look'!B8 -> Property4
F20: ='New Mortgage look'!B53 -> KiwiBank 2 - 8 Denning Place | G20: ='New Mortgage look'!C53 -> 38-9016-xxxxx-06 | H20: ='New Mortgage look'!D53 -> 100000 | J20: ='New Mortgage look'!E53 -> 0.0654
F21: ='New Mortgage look'!B54 -> KiwiBank 3 - 8 Denning Place | G21: ='New Mortgage look'!C54 -> 38-9016-xxxxx-07 | H21: ='New Mortgage look'!D54 -> 60000 | J21: ='New Mortgage look'!E54 -> 0.0654
F22: ='New Mortgage look'!B55 -> KiwiBank 4 - 8 Denning Place | G22: ='New Mortgage look'!C55 -> 38-9016-xxxxx-08 | H22: ='New Mortgage look'!D55 -> 40000 | J22: ='New Mortgage look'!E55 -> 0.0664
E23: ='New Mortgage look'!B5 -> Property1
F24: ='New Mortgage look'!B56 -> KiwiBank 5 - 6/29 Te Koa Road | G24: ='New Mortgage look'!C56 -> 38-9016-xxxxx-14 | H24: ='New Mortgage look'!D56 -> 30000 | J24: ='New Mortgage look'!E56 -> 0.0575
F25: ='New Mortgage look'!B57 -> KiwiBank 6 - 6/29 Te Koa Road | G25: ='New Mortgage look'!C57 -> 38-9016-xxxxx-15 | H25: ='New Mortgage look'!D57 -> 30000 | J25: ='New Mortgage look'!E57 -> 0.0575
B29: Summary
C30: MJ | H30: =SUM(H11:H13)+H5 -> 200002 | I30: =SUM(I11:I13)+I5 -> 0
C31: SAM | H31: =H17+SUM(H6:H7) -> 91500 | I31: =SUM(I16:I17)+SUM(I6:I7) -> 0
C32: SAM&MJ | H32: =SUM(H20:H22)+SUM(H24:H25) -> 260000 | I32: =SUM(I20:I22)+SUM(I24:I25) -> 0
B34: Category
C35: Credit Cards | H35: =SUM(H5:H7) -> 1502 | I35: =SUM(I5:I7) -> 0
C36: ="Mortgage1-"&E10 -> Mortgage1-Property3 | H36: =SUM(H11:H13) -> 200000 | I36: =SUM(I11:I13) -> 0
C37: ="Mortgage2-"&E15 -> Mortgage2-Propert2 | H37: =H17 -> 90000 | I37: =SUM(I16:I17) -> 0
C38: ="Mortgage3-"&E19 -> Mortgage3-Property4 | H38: =SUM(H20:H22) -> 200000 | I38: =SUM(I20:I22) -> 0
C39: ="Mortgage4-"&E23 -> Mortgage4-Property1 | H39: =SUM(H24:H25) -> 60000 | I39: =SUM(I24:I25) -> 0
B43: Total | H43: =SUM(H30:H32) -> 551502 | I43: =SUM(I30:I32) -> 0

Sheet Income
B3: Income
C4: Salary | G4: (gross)/month | H4: Linda Loan Assest
D5: MJ | E5: BidONE | G5: ='New Mortgage look'!D80+'New Mortgage look'!E80+'New Mortgage look'!F80+'New Mortgage look'!H80 -> 4062.5
D6: SAM | E6: KiwiBank | G6: ='New Mortgage look'!D81+'New Mortgage look'!E81+'New Mortgage look'!F81+'New Mortgage look'!H81 -> 3020.8333
C7: Rental Income
D8: MJ | E8: ='New Mortgage look'!B7 -> Property3 | G8: ='New Mortgage look'!D92 -> 808.88889
D9: SAM | E9: ='New Mortgage look'!B6 -> Propert2 | G9: ='New Mortgage look'!D93 -> 1315.7895
D10: MJ&SAM | E10: ='New Mortgage look'!B5 -> Property1 | G10: ='New Mortgage look'!D91 -> 0
B14: Summary
C15: MJ | G15: =G5+G8 -> 4871.3889
C16: SAM | G16: =G6+G9 -> 4336.6228
C17: MJ&SAM | G17: =G10 -> 0
B20: Category
C21: =C4&" "&D5 -> Salary MJ | G21: =G5 -> 4062.5
C22: =C4&" "&D6 -> Salary SAM | G22: =G6 -> 3020.8333
C23: =C7&" "&E8 -> Rental Income Property3 | G23: =G8 -> 808.88889
C24: =C7&""&E9 -> Rental IncomePropert2 | G24: =G9 -> 1315.7895
C25: =C7&""&E10 -> Rental IncomeProperty1 | G25: =G10 -> 0
B28: Total | G28: =SUM(G15:G17) -> 9208.0117

Sheet Expenses
B2: Expenses | L2: Category | Q2: Monthly | R2: Linda Loan Assest
C3: Groceries | H3: Monthly | I3: Linda Loan Assest | M3: =C3 -> Groceries | Q3: =H4 -> 387.64 | R3: =I4 -> 511.5
D4: Groceries | H4: 387.64 | I4: =SIGN(H4) * ROUND(RAND() * ABS(H4) * 1.5, 2) -> 511.5 | M4: =C5 -> Personal Care | Q4: =SUM(H6:H7) -> 421.05 | R4: =SUM(I6:I7) -> 473.22
C5: Personal Care | H5: 0 | I5: =SIGN(H5) * ROUND(RAND() * ABS(H5) * 1.5, 2) -> 0 | M5: =C8 -> Medical | Q5: =H9 -> 13.16 | R5: =I9 -> 5.83
D6: Clothing & Footwear | H6: 67.57 | I6: =SIGN(H6) * ROUND(RAND() * ABS(H6) * 1.5, 2) -> 79.47 | M6: =C10 -> Recreational & Entertainment | Q6: =SUM(H11:H14) -> 1999.34 | R6: =SUM(I11:I14) -> 2333.78
D7: Personal Care | H7: 353.48 | I7: =SIGN(H7) * ROUND(RAND() * ABS(H7) * 1.5, 2) -> 393.75 | M7: =C15 -> Telephone & Internet | Q7: =SUM(H16:H17) -> 42.73 | R7: =SUM(I16:I17) -> 26.32
C8: Medical | H8: 0 | I8: =SIGN(H8) * ROUND(RAND() * ABS(H8) * 1.5, 2) -> 0 | M8: =C18 -> Transport | Q8: =H19 -> 302.07 | R8: =I19 -> 394.76
D9: Medical & Health | H9: 13.16 | I9: =SIGN(H9) * ROUND(RAND() * ABS(H9) * 1.5, 2) -> 5.83 | M9: =C20 -> Insurance | Q9: =SUM(H21:H23) -> 103.45 | R9: =SUM(I21:I23) -> 68.06
C10: Recreational & Entertainment | H10: 0 | I10: =SIGN(H10) * ROUND(RAND() * ABS(H10) * 1.5, 2) -> 0 | M10: =C24 -> Property4 | Q10: =SUM(H25:H30) -> 632.65 | R10: =SUM(I25:I30) -> 463.42
D11: Dining Out | H11: 105.62 | I11: =SIGN(H11) * ROUND(RAND() * ABS(H11) * 1.5, 2) -> 154.34 | M11: =C31 -> Property3 | Q11: =SUM(H32:H34) -> 327.93 | R11: =SUM(I32:I34) -> 189.77
D12: Entertainment | H12: 475.14 | I12: =SIGN(H12) * ROUND(RAND() * ABS(H12) * 1.5, 2) -> 644.58 | M12: =C35 -> Propert2 | Q12: =SUM(H36:H38) -> 90.71 | R12: =SUM(I36:I38) -> 59.07
D13: Travel | H13: 1252.26 | I13: =SIGN(H13) * ROUND(RAND() * ABS(H13) * 1.5, 2) -> 1297.24 | M13: =C39 -> Property1 | Q13: =SUM(H40:H42) -> 230.55 | R13: =SUM(I40:I42) -> 263.84
D14: Gym | H14: 166.32 | I14: =SIGN(H14) * ROUND(RAND() * ABS(H14) * 1.5, 2) -> 237.62 | M14: =C43 -> Other | Q14: =SUM(H44:H50) -> 657.57 | R14: =SUM(I44:I50) -> 341.32
C15: Telephone & Internet | H15: 0 | I15: =SIGN(H15) * ROUND(RAND() * ABS(H15) * 1.5, 2) -> 0 | M15: =C51 -> Loans and Liabilities | Q15: =SUM(H52:H58) -> 907.86 | R15: =SUM(I52:I58) -> 108.7
D16: Mobile phone | H16: 42.73 | I16: =SIGN(H16) * ROUND(RAND() * ABS(H16) * 1.5, 2) -> 26.32
D17: Internet | H17: 0 | I17: =SIGN(H17) * ROUND(RAND() * ABS(H17) * 1.5, 2) -> 0 | L17: Total | Q17: =SUM(Q3:Q15) -> 6116.71 | R17: =SUM(R3:R15) -> 5239.59
C18: Transport | H18: 0 | I18: =SIGN(H18) * ROUND(RAND() * ABS(H18) * 1.5, 2) -> 0
D19: Petrol | H19: 302.07 | I19: =SIGN(H19) * ROUND(RAND() * ABS(H19) * 1.5, 2) -> 394.76
C20: Insurance | H20: 0 | I20: =SIGN(H20) * ROUND(RAND() * ABS(H20) * 1.5, 2) -> 0
D21: Health Insurance-SAM | H21: 49.33 | I21: =SIGN(H21) * ROUND(RAND() * ABS(H21) * 1.5, 2) -> 12.18
D22: Life Insurance | H22: 48.87 | I22: =SIGN(H22) * ROUND(RAND() * ABS(H22) * 1.5, 2) -> 48.22
D23: Vehicle Insurance | H23: 5.25 | I23: =SIGN(H23) * ROUND(RAND() * ABS(H23) * 1.5, 2) -> 7.66
C24: ='New Mortgage look'!B8 -> Property4 | H24: 0 | I24: =SIGN(H24) * ROUND(RAND() * ABS(H24) * 1.5, 2) -> 0
D25: Electricity & Gas & Internet | H25: 35.14 | I25: =SIGN(H25) * ROUND(RAND() * ABS(H25) * 1.5, 2) -> 6.95
D26: Council Rates | H26: 118.59 | I26: =SIGN(H26) * ROUND(RAND() * ABS(H26) * 1.5, 2) -> 55.8
D27: Water | H27: 71.16 | I27: =SIGN(H27) * ROUND(RAND() * ABS(H27) * 1.5, 2) -> 38.39
D28: 8Denning-HouseInsurance | H28: 2.49 | I28: =SIGN(H28) * ROUND(RAND() * ABS(H28) * 1.5, 2) -> 0.86
D29: 8Denning-ContentsInsurance | H29: 34.32 | I29: =SIGN(H29) * ROUND(RAND() * ABS(H29) * 1.5, 2) -> 29.98
D30: Home Expense - Furnishings | H30: 370.95 | I30: =SIGN(H30) * ROUND(RAND() * ABS(H30) * 1.5, 2) -> 331.44
C31: ='New Mortgage look'!B7 -> Property3 | H31: 0 | I31: =SIGN(H31) * ROUND(RAND() * ABS(H31) * 1.5, 2) -> 0
D32: Council Rates | H32: 220.48 | I32: =SIGN(H32) * ROUND(RAND() * ABS(H32) * 1.5, 2) -> 103.48
D33: House Insurance | H33: 20.12 | I33: =SIGN(H33) * ROUND(RAND() * ABS(H33) * 1.5, 2) -> 24
D34: Property Tax | H34: 87.33 | I34: =SIGN(H34) * ROUND(RAND() * ABS(H34) * 1.5, 2) -> 62.29
C35: ='New Mortgage look'!B6 -> Propert2 | H35: 0 | I35: =SIGN(H35) * ROUND(RAND() * ABS(H35) * 1.5, 2) -> 0
D36: Council Rates | H36: 28.77 | I36: =SIGN(H36) * ROUND(RAND() * ABS(H36) * 1.5, 2) -> 4.21
D37: House Insurance | H37: 39.66 | I37: =SIGN(H37) * ROUND(RAND() * ABS(H37) * 1.5, 2) -> 51.6
D38: Property Tax | H38: 22.28 | I38: =SIGN(H38) * ROUND(RAND() * ABS(H38) * 1.5, 2) -> 3.26
C39: ='New Mortgage look'!B5 -> Property1 | H39: 0 | I39: =SIGN(H39) * ROUND(RAND() * ABS(H39) * 1.5, 2) -> 0
D40: Council Rates | H40: 196.74 | I40: =SIGN(H40) * ROUND(RAND() * ABS(H40) * 1.5, 2) -> 258.84
D41: House Insurance | H41: 33.81 | I41: =SIGN(H41) * ROUND(RAND() * ABS(H41) * 1.5, 2) -> 5
...

Sheet Summary
A1: =Income!B3 -> Income | C1: =Income!G4 -> (gross)/month | E1: =Expenses!B2 -> Expenses | G1: Monthly
B2: =Income!C21 -> Salary MJ | C2: =Income!G21 -> 4062.5 | F2: =Expenses!M3 -> Groceries | G2: =Expenses!Q3 -> 387.64
B3: =Income!C22 -> Salary SAM | C3: =Income!G22 -> 3020.8333 | F3: =Expenses!M4 -> Personal Care | G3: =Expenses!Q4 -> 421.05
B4: =Income!C23 -> Rental Income Property3 | C4: =Income!G23 -> 808.88889 | F4: =Expenses!M5 -> Medical | G4: =Expenses!Q5 -> 13.16
B5: =Income!C24 -> Rental IncomePropert2 | C5: =Income!G24 -> 1315.7895 | F5: =Expenses!M6 -> Recreational & Entertainment | G5: =Expenses!Q6 -> 1999.34
B6: =Income!C25 -> Rental IncomeProperty1 | C6: =Income!G25 -> 0 | F6: =Expenses!M7 -> Telephone & Internet | G6: =Expenses!Q7 -> 42.73
A7: Total | C7: =SUM(C2:C6) -> 9208.0117 | F7: =Expenses!M8 -> Transport | G7: =Expenses!Q8 -> 302.07
F8: =Expenses!M9 -> Insurance | G8: =Expenses!Q9 -> 103.45
F9: =Expenses!M10 -> Property4 | G9: =Expenses!Q10 -> 632.65
F10: =Expenses!M11 -> Property3 | G10: =Expenses!Q11 -> 327.93
A11: =Assets!B3 -> Assets | F11: =Expenses!M12 -> Propert2 | G11: =Expenses!Q12 -> 90.71
B12: =Assets!C27 -> Saving & Cash | C12: =Assets!G27 -> 26500 | F12: =Expenses!M13 -> Property1 | G12: =Expenses!Q13 -> 230.55
B13: =Assets!C28 -> Superannuation | C13: =Assets!G28 -> 80000 | F13: =Expenses!M14 -> Other | G13: =Expenses!Q14 -> 657.57
B14: =Assets!C29 -> Property | C14: =Assets!G29 -> 600000 | F14: =Expenses!M15 -> Loans and Liabilities | G14: =Expenses!Q15 -> 907.86
B15: =Assets!C30 -> Vehicle | C15: =Assets!G30 -> 20000 | F15: ='New Mortgage look'!H18 -> Salary- ACC | G15: ='New Mortgage look'!I18 -> 103.605
B16: =Assets!C31 -> Contents | C16: =Assets!G31 -> 20000 | F16: ='New Mortgage look'!H19 -> Salary - Tax | G16: ='New Mortgage look'!I19 -> 1934.48
A17: Total | C17: =SUM(C12:C16) -> 746500 | E17: Total | G17: =SUM(G2:G16) -> 8154.795
E19: Income-Expenses | G19: =C7-G17 -> 1053.2167
A21: =Liabilities!B3 -> Liabilities
B22: =Liabilities!C35 -> Credit Cards | C22: =Liabilities!H35 -> 1502
B23: =Liabilities!C36 -> Mortgage1-Property3 | C23: =Liabilities!H36 -> 200000
B24: =Liabilities!C37 -> Mortgage2-Propert2 | C24: =Liabilities!H37 -> 90000
B25: =Liabilities!C38 -> Mortgage3-Property4 | C25: =Liabilities!H38 -> 200000
B26: =Liabilities!C39 -> Mortgage4-Property1 | C26: =Liabilities!H39 -> 60000
A27: Total | C27: =SUM(C22:C26) -> 551502
A30: Properties | C30: Value | D30: Current Loan | E30: Mortgage (Monthly) | F30: Tax (Monthly) | G30: Rate (Monthly) | H30: Insurance(Monthly) | I30: Rent Income (Monthly) | J30: Net (Monthly)
B31: ='New Mortgage look'!B8 -> Property4 | C31: ='New Mortgage look'!C8 -> 180000 | D31: ='New Mortgage look'!D8 -> 200000 | E31: ='New Mortgage look'!K8*52/12 -> 585 | F31: ='New Mortgage look'!O8*52/12 -> 0 | G31: ='New Mortgage look'!S8*52/12 -> 250 | H31: ='New Mortgage look'!W8*52/12 -> 50 | I31: ='New Mortgage look'!I8*52/12 -> 0 | J31: =I31-SUM(E31:H31) -> -885
B32: ='New Mortgage look'!B7 -> Property3 | C32: ='New Mortgage look'!C7 -> 170000 | D32: ='New Mortgage look'!D7 -> 200000 | E32: ='New Mortgage look'!K7*52/12 -> 260 | F32: ='New Mortgage look'!O7*52/12 -> 112.766 | G32: ='New Mortgage look'!S7*52/12 -> 291.66667 | H32: ='New Mortgage look'!W7*52/12 -> 40 | I32: ='New Mortgage look'!I7*52/12 -> 2600 | J32: =I32-SUM(E32:H32) -> 1895.5673
B33: ='New Mortgage look'!B6 -> Propert2 | C33: ='New Mortgage look'!C6 -> 150000 | D33: ='New Mortgage look'!D6 -> 90000 | E33: ='New Mortgage look'!K6*52/12 -> 173.33333 | F33: ='New Mortgage look'!O6*52/12 -> 135.16167 | G33: ='New Mortgage look'!S6*52/12 -> 166.66667 | H33: ='New Mortgage look'!W6*52/12 -> 50 | I33: ='New Mortgage look'!I6*52/12 -> 2166.6667 | J33: =I33-SUM(E33:H33) -> 1641.505
B34: ='New Mortgage look'!B5 -> Property1 | C34: ='New Mortgage look'!C5 -> 100000 | D34: ='New Mortgage look'!D5 -> 60000 | E34: ='New Mortgage look'!K5*52/12 -> 433.33333 | F34: ='New Mortgage look'!O5*52/12 -> 0 | G34: ='New Mortgage look'!S5*52/12 -> 166.66667 | H34: ='New Mortgage look'!W5*52/12 -> 60 | I34: ='New Mortgage look'!I5*52/12 -> 433.33333 | J34: =I34-SUM(E34:H34) -> -226.66667
A35: Total | C35: =SUM(C31:C33) -> 500000 | D35: =SUM(D31:D33) -> 490000 | E35: =SUM(E31:E33) -> 1018.3333 | F35: =SUM(F31:F33) -> 247.92767 | G35: =SUM(G31:G33) -> 708.33333 | H35: =SUM(H31:H33) -> 140 | I35: =SUM(I31:I33) -> 4766.6667 | J35: =SUM(J31:J34) -> 2425.4057
